Workbook

Sheet Dashboard
B2: NextEra Energy — Dashboard
B3: Valuation Date: 08/03/2026
B5: Valuation Summary ($/share)
B6: DDM | C6: ='DDM Model'!D33 -> 79.930552
B7: SOTP | C7: ='SOTP & Multiples'!F57 -> 86.33087
B8: RIM | C8: ='Residual Income Model'!D32 -> 107.34207
B9: Current Price | C9: ='DDM Model'!D13 -> 86.55
B11: Chart Data | C11: 2023A | D11: 2024A | E11: 2025A | F11: 2026E | G11: 2027E | H11: 2028E | I11: 2029E | J11: 2030E | K11: 2031E | L11: 2032E
B12: Revenue ($M) | C12: ='3-Statement Model'!J18 -> 28114 | D12: ='3-Statement Model'!K18 -> 24753 | E12: ='3-Statement Model'!L18 -> 27412 | F12: ='3-Statement Model'!M18 -> 30153.2 | G12: ='3-Statement Model'!N18 -> 33168.52 | H12: ='3-Statement Model'!O18 -> 36419.035 | I12: ='3-Statement Model'!P18 -> 39878.843 | J12: ='3-Statement Model'!Q18 -> 43587.576 | ... L12: ='3-Statement Model'!S18 -> 51929.017
B13: Adjusted EPS ($) | C13: 3.17 | D13: 3.43 | E13: 3.71 | F13: ='Residual Income Model'!C17 -> 4.0000162 | G13: ='Residual Income Model'!D17 -> 4.3148302 | H13: ='Residual Income Model'!E17 -> 4.6568364 | I13: ='Residual Income Model'!F17 -> 5.0245897 | J13: ='Residual Income Model'!G17 -> 5.4207962 | K13: ='Residual Income Model'!H17 -> 5.851148 | L13: ='Residual Income Model'!I17 -> 6.3111196
B14: DPS ($) | C14: 1.87 | D14: 2.06 | E14: 2.27 | F14: ='DDM Model'!C21 -> 2.497227 | G14: ='DDM Model'!D21 -> 2.6470606 | H14: ='DDM Model'!E21 -> 2.8058843 | I14: ='DDM Model'!F21 -> 2.9622121 | J14: ='DDM Model'!G21 -> 3.1145544 | K14: ='DDM Model'!H21 -> 3.2613834 | L14: ='DDM Model'!I21 -> 3.401157
B15: Capex ($M) | C15: =-'3-Statement Model'!J37 -> 25113 | D15: =-'3-Statement Model'!K37 -> 24729 | E15: =-'3-Statement Model'!L37 -> 24606 | F15: =-'3-Statement Model'!M37 -> 27999.96 | G15: =-'3-Statement Model'!N37 -> 30500.113 | H15: =-'3-Statement Model'!O37 -> 32440.984 | I15: =-'3-Statement Model'!P37 -> 34437.375 | J15: =-'3-Statement Model'!Q37 -> 36033.413 | ... L15: =-'3-Statement Model'!S37 -> 38670.501
B16: Net debt / EBITDA | C16: =('3-Statement Model'!J51-'3-Statement Model'!J47)/'3-Statement Model'!J22 -> 4.3758377 | D16: =('3-Statement Model'!K51-'3-Statement Model'!K47)/'3-Statement Model'!K22 -> 6.2472761 | E16: =('3-Statement Model'!L51-'3-Statement Model'!L47)/'3-Statement Model'!L22 -> 6.245424 | F16: =('3-Statement Model'!M51-'3-Statement Model'!M47)/'3-Statement Model'!M22 -> 6.7177826 | G16: =('3-Statement Model'!N51-'3-Statement Model'!N47)/'3-Statement Model'!N22 -> 6.7177826 | H16: =('3-Statement Model'!O51-'3-Statement Model'!O47)/'3-Statement Model'!O22 -> 6.7177826 | I16: =('3-Statement Model'!P51-'3-Statement Model'!P47)/'3-Statement Model'!P22 -> 6.7177826 | J16: =('3-Statement Model'!Q51-'3-Statement Model'!Q47)/'3-Statement Model'!Q22 -> 6.7177826 | ... L16: =('3-Statement Model'!S51-'3-Statement Model'!S47)/'3-Statement Model'!S22 -> 6.7177826
B17: ROIC | C17: =('3-Statement Model'!J24*(1-'3-Statement Model'!J12))/('3-Statement Model'!J51+'3-Statement Model'!J53+'3-Statement Model'!J54-'3-Statement Model'!J47) -> 0.068781691 | D17: =('3-Statement Model'!K24*(1-'3-Statement Model'!K12))/('3-Statement Model'!K51+'3-Statement Model'!K53+'3-Statement Model'!K54-'3-Statement Model'!K47) -> 0.049955602 | E17: =('3-Statement Model'!L24*(1-'3-Statement Model'!L12))/('3-Statement Model'!L51+'3-Statement Model'!L53+'3-Statement Model'!L54-'3-Statement Model'!L47) -> 0.061184958 | F17: =('3-Statement Model'!M24*(1-'3-Statement Model'!M12))/('3-Statement Model'!M51+'3-Statement Model'!M53+'3-Statement Model'!M54-'3-Statement Model'!M47) -> 0.050952357 | G17: =('3-Statement Model'!N24*(1-'3-Statement Model'!N12))/('3-Statement Model'!N51+'3-Statement Model'!N53+'3-Statement Model'!N54-'3-Statement Model'!N47) -> 0.047997173 | H17: =('3-Statement Model'!O24*(1-'3-Statement Model'!O12))/('3-Statement Model'!O51+'3-Statement Model'!O53+'3-Statement Model'!O54-'3-Statement Model'!O47) -> 0.045628088 | I17: =('3-Statement Model'!P24*(1-'3-Statement Model'!P12))/('3-Statement Model'!P51+'3-Statement Model'!P53+'3-Statement Model'!P54-'3-Statement Model'!P47) -> 0.043739095 | J17: =('3-Statement Model'!Q24*(1-'3-Statement Model'!Q12))/('3-Statement Model'!Q51+'3-Statement Model'!Q53+'3-Statement Model'!Q54-'3-Statement Model'!Q47) -> 0.042345572 | ... L17: =('3-Statement Model'!S24*(1-'3-Statement Model'!S12))/('3-Statement Model'!S51+'3-Statement Model'!S53+'3-Statement Model'!S54-'3-Statement Model'!S47) -> 0.041950884
B18: WACC | C18: =('3-Statement Model'!J53/('3-Statement Model'!J53+'3-Statement Model'!J54+'3-Statement Model'!J51))*'DDM Model'!$D$9+('3-Statement Model'!J54/('3-Statement Model'!J53+'3-Statement Model'!J54+'3-Statement Model'!J51))*'3-Statement Model'!J14*(1-0.21)+('3-Statement Model'!J51/('3-Statement Model'!J53+'3-Statement Model'!J54+'3-Statement Model'!J51))*'3-Statement Model'!J14*(1-0.21) -> 0.04173854 | D18: =('3-Statement Model'!K53/('3-Statement Model'!K53+'3-Statement Model'!K54+'3-Statement Model'!K51))*'DDM Model'!$D$9+('3-Statement Model'!K54/('3-Statement Model'!K53+'3-Statement Model'!K54+'3-Statement Model'!K51))*'3-Statement Model'!K14*(1-0.21)+('3-Statement Model'!K51/('3-Statement Model'!K53+'3-Statement Model'!K54+'3-Statement Model'!K51))*'3-Statement Model'!K14*(1-0.21) -> 0.041050951 | E18: =('3-Statement Model'!L53/('3-Statement Model'!L53+'3-Statement Model'!L54+'3-Statement Model'!L51))*'DDM Model'!$D$9+('3-Statement Model'!L54/('3-Statement Model'!L53+'3-Statement Model'!L54+'3-Statement Model'!L51))*'3-Statement Model'!L14*(1-0.21)+('3-Statement Model'!L51/('3-Statement Model'!L53+'3-Statement Model'!L54+'3-Statement Model'!L51))*'3-Statement Model'!L14*(1-0.21) -> 0.042671058 | F18: =('3-Statement Model'!M53/('3-Statement Model'!M53+'3-Statement Model'!M54+'3-Statement Model'!M51))*'DDM Model'!$D$9+('3-Statement Model'!M54/('3-Statement Model'!M53+'3-Statement Model'!M54+'3-Statement Model'!M51))*'3-Statement Model'!M14*(1-0.21)+('3-Statement Model'!M51/('3-Statement Model'!M53+'3-Statement Model'!M54+'3-Statement Model'!M51))*'3-Statement Model'!M14*(1-0.21) -> 0.044179865 | G18: =('3-Statement Model'!N53/('3-Statement Model'!N53+'3-Statement Model'!N54+'3-Statement Model'!N51))*'DDM Model'!$D$9+('3-Statement Model'!N54/('3-Statement Model'!N53+'3-Statement Model'!N54+'3-Statement Model'!N51))*'3-Statement Model'!N14*(1-0.21)+('3-Statement Model'!N51/('3-Statement Model'!N53+'3-Statement Model'!N54+'3-Statement Model'!N51))*'3-Statement Model'!N14*(1-0.21) -> 0.044891139 | H18: =('3-Statement Model'!O53/('3-Statement Model'!O53+'3-Statement Model'!O54+'3-Statement Model'!O51))*'DDM Model'!$D$9+('3-Statement Model'!O54/('3-Statement Model'!O53+'3-Statement Model'!O54+'3-Statement Model'!O51))*'3-Statement Model'!O14*(1-0.21)+('3-Statement Model'!O51/('3-Statement Model'!O53+'3-Statement Model'!O54+'3-Statement Model'!O51))*'3-Statement Model'!O14*(1-0.21) -> 0.045641055 | I18: =('3-Statement Model'!P53/('3-Statement Model'!P53+'3-Statement Model'!P54+'3-Statement Model'!P51))*'DDM Model'!$D$9+('3-Statement Model'!P54/('3-Statement Model'!P53+'3-Statement Model'!P54+'3-Statement Model'!P51))*'3-Statement Model'!P14*(1-0.21)+('3-Statement Model'!P51/('3-Statement Model'!P53+'3-Statement Model'!P54+'3-Statement Model'!P51))*'3-Statement Model'!P14*(1-0.21) -> 0.045882651 | J18: =('3-Statement Model'!Q53/('3-Statement Model'!Q53+'3-Statement Model'!Q54+'3-Statement Model'!Q51))*'DDM Model'!$D$9+('3-Statement Model'!Q54/('3-Statement Model'!Q53+'3-Statement Model'!Q54+'3-Statement Model'!Q51))*'3-Statement Model'!Q14*(1-0.21)+('3-Statement Model'!Q51/('3-Statement Model'!Q53+'3-Statement Model'!Q54+'3-Statement Model'!Q51))*'3-Statement Model'!Q14*(1-0.21) -> 0.046730657 | ... L18: =('3-Statement Model'!S53/('3-Statement Model'!S53+'3-Statement Model'!S54+'3-Statement Model'!S51))*'DDM Model'!$D$9+('3-Statement Model'!S54/('3-Statement Model'!S53+'3-Statement Model'!S54+'3-Statement Model'!S51))*'3-Statement Model'!S14*(1-0.21)+('3-Statement Model'!S51/('3-Statement Model'!S53+'3-Statement Model'!S54+'3-Statement Model'!S51))*'3-Statement Model'!S14*(1-0.21) -> 0.046333862
B19: GAAP EPS ($) | C19: ='3-Statement Model'!J30/'SOTP & Multiples'!$C$17 -> 3.5296958 | D19: ='3-Statement Model'!K30/'SOTP & Multiples'!$C$17 -> 3.3539353 | E19: ='3-Statement Model'!L30/'SOTP & Multiples'!$C$17 -> 3.300338 | F19: ='3-Statement Model'!M30/'SOTP & Multiples'!$C$17 -> 3.7240652 | G19: ='3-Statement Model'!N30/'SOTP & Multiples'!$C$17 -> 3.6469519 | H19: ='3-Statement Model'!O30/'SOTP & Multiples'!$C$17 -> 3.6839293 | I19: ='3-Statement Model'!P30/'SOTP & Multiples'!$C$17 -> 3.775603 | J19: ='3-Statement Model'!Q30/'SOTP & Multiples'!$C$17 -> 3.8178611 | ... L19: ='3-Statement Model'!S30/'SOTP & Multiples'!$C$17 -> 4.3383795
B20: Adj. EPS growth % | D20: =D13/C13-1 -> 0.082018927 | E20: =E13/D13-1 -> 0.081632653 | F20: =F13/E13-1 -> 0.078171489 | G20: =G13/F13-1 -> 0.078703176 | H20: =H13/G13-1 -> 0.079262967 | I20: =I13/H13-1 -> 0.07897061 | J20: =J13/I13-1 -> 0.078853512 | K20: =K13/J13-1 -> 0.079389031 | L20: =L13/K13-1 -> 0.0786122
B21: DPS growth % | D21: =D14/C14-1 -> 0.10160428 | E21: =E14/D14-1 -> 0.10194175 | F21: =F14/E14-1 -> 0.1001 | G21: =G14/F14-1 -> 0.06 | H21: =H14/G14-1 -> 0.06 | I21: =I14/H14-1 -> 0.055714286 | J21: =J14/I14-1 -> 0.051428571 | K21: =K14/J14-1 -> 0.047142857 | L21: =L14/K14-1 -> 0.042857143

Sheet 3-Statement Model
B2: NextEra Energy — 3-Statement Model
B3: Valuation Date: 08/03/2026
B4: $ in Millions | C4: 2016A | D4: 2017A | E4: 2018A | F4: 2019A | G4: 2020A | H4: 2021A | I4: 2022A | J4: 2023A | K4: 2024A | L4: 2025A | M4: 2026E | N4: 2027E | O4: 2028E | P4: 2029E | Q4: 2030E | R4: 2031E | S4: 2032E | T4: 2033E | U4: 2034E | V4: 2035E
B6: Assumptions
B7: Revenue growth % | D7: =D18/C18-1 -> 0.064134341 | E7: =E18/D18-1 -> -0.025971001 | F7: =F18/E18-1 -> 0.14808394 | G7: =G18/F18-1 -> -0.062851489 | H7: =H18/G18-1 -> -0.05156415 | I7: =I18/H18-1 -> 0.22772277 | J7: =J18/I18-1 -> 0.34157282 | K7: =K18/J18-1 -> -0.11954898 | L7: =L18/K18-1 -> 0.10742132 | M7: 0.1 | N7: 0.1 | O7: 0.098 | P7: 0.095 | Q7: 0.093 | R7: 0.092 | S7: 0.091 | T7: 0.09 | U7: 0.09 | V7: 0.09
B8: Cost of sales (fuel) % rev | C8: =-C19/C18 -> 0.24736646 | D8: =-D19/D18 -> 0.23705817 | E8: =-E19/E18 -> 0.22311233 | F8: =-F19/F18 -> 0.22719225 | G8: =-G19/G18 -> 0.19664389 | H8: =-H19/H18 -> 0.26521765 | I8: =-I19/I18 -> 0.30487688 | J8: =-J19/J18 -> 0.19410258 | ... L8: =-L19/L18 -> 0.18035897 | M8: 0.18 | N8: 0.18 | O8: 0.18 | P8: 0.18 | Q8: 0.18 | R8: 0.18 | S8: 0.18 | T8: 0.18 | U8: 0.18 | V8: 0.18
B9: Operating expenses % rev | C9: =-C21/C18 -> 0.28299665 | D9: =-D21/D18 -> 0.32446282 | E9: =-E21/E18 -> 0.28720033 | F9: =-F21/F18 -> 0.27452614 | G9: =-G21/G18 -> 0.29393788 | H9: =-H21/H18 -> 0.33423165 | I9: =-I21/I18 -> 0.28550296 | J9: =-J21/J18 -> 0.23265988 | ... L9: =-L21/L18 -> 0.27754268 | M9: 0.277 | N9: 0.277 | O9: 0.277 | P9: 0.277 | Q9: 0.277 | R9: 0.277 | S9: 0.277 | T9: 0.277 | U9: 0.277 | V9: 0.277
B10: Other income % rev | C10: =('16''-25'' 10Ks'!C29-'16''-25'' 10Ks'!C17-'16''-25'' 10Ks'!C21)/'16''-25'' 10Ks'!C8 -> 0.063018961 | D10: =('16''-25'' 10Ks'!D29-'16''-25'' 10Ks'!D17-'16''-25'' 10Ks'!D21)/'16''-25'' 10Ks'!D8 -> 0.061026029 | E10: =('16''-25'' 10Ks'!E29-'16''-25'' 10Ks'!E17-'16''-25'' 10Ks'!E21)/'16''-25'' 10Ks'!E8 -> 0.27321098 | F10: =('16''-25'' 10Ks'!F29-'16''-25'' 10Ks'!F17-'16''-25'' 10Ks'!F21)/'16''-25'' 10Ks'!F8 -> 0.038117059 | G10: =('16''-25'' 10Ks'!G29-'16''-25'' 10Ks'!G17-'16''-25'' 10Ks'!G21)/'16''-25'' 10Ks'!G8 -> -0.041840307 | H10: =('16''-25'' 10Ks'!H29-'16''-25'' 10Ks'!H17-'16''-25'' 10Ks'!H21)/'16''-25'' 10Ks'!H8 -> 0.089753354 | I10: =('16''-25'' 10Ks'!I29-'16''-25'' 10Ks'!I17-'16''-25'' 10Ks'!I21)/'16''-25'' 10Ks'!I8 -> 0.016033594 | J10: =('16''-25'' 10Ks'!J29-'16''-25'' 10Ks'!J17-'16''-25'' 10Ks'!J21)/'16''-25'' 10Ks'!J8 -> 0.01333855 | ... L10: =('16''-25'' 10Ks'!L29-'16''-25'' 10Ks'!L17-'16''-25'' 10Ks'!L21)/'16''-25'' 10Ks'!L8 -> 0.029986867 | M10: 0.03 | N10: 0.03 | O10: 0.03 | P10: 0.03 | Q10: 0.03 | R10: 0.03 | S10: 0.03 | T10: 0.03 | U10: 0.03 | V10: 0.03
B11: Depreciation % of PP&E | D11: =-D23/C46 -> 0.035225371 | E11: =-E23/D46 -> 0.054102284 | F11: =-F23/E46 -> 0.05994256 | G11: =-G23/F46 -> 0.049408609 | H11: =-H23/G46 -> 0.042743701 | I11: =-I23/H46 -> 0.045325522 | J11: =-J23/I46 -> 0.052935827 | K11: =-K23/J46 -> 0.043426409 | L11: =-L23/K46 -> 0.047388586 | M11: 0.042 | N11: 0.042 | O11: 0.042 | P11: 0.042 | Q11: 0.042 | R11: 0.042 | S11: 0.042 | T11: 0.042 | U11: 0.042 | V11: 0.042
B12: Effective tax rate | C12: =-C27/C26 -> 0.31498401 | D12: =-D27/D26 -> -0.14153978 | E12: =-E27/E26 -> 0.21436344 | F12: =-F27/F26 -> 0.11678832 | G12: =-G27/G26 -> 0.018234563 | H12: =-H27/H26 -> 0.1096063 | I12: =-I27/I26 -> 0.15292276 | J12: =-J27/J26 -> 0.13803513 | ... L12: =-L27/L26 -> -0.17704194 | M12: 0.06 | N12: 0.07 | O12: 0.08 | P12: 0.09 | Q12: 0.1 | R12: 0.1 | S12: 0.1 | T12: 0.1 | U12: 0.1 | V12: 0.1
B13: Capex % rev | C13: =-C37/C18 -> 0.59710001 | D13: =-D37/D18 -> 0.62540034 | E13: =-E37/E18 -> 0.77742572 | F13: =-F37/F18 -> 0.90928973 | G13: =-G37/G18 -> 0.81180197 | H13: =-H37/H18 -> 0.94188295 | I13: =-I37/I18 -> 0.92016606 | J13: =-J37/J18 -> 0.89325603 | ... L13: =-L37/L18 -> 0.89763607 | M13: 0.92859 | N13: 0.91955 | O13: 0.89077 | P13: 0.86355 | Q13: 0.82669 | R13: 0.79367 | S13: 0.74468 | T13: 0.67828 | U13: 0.61511 | V13: 0.5616
B14: Cost of debt | C14: ='16''-25'' 10Ks'!C201 -> 0.039453467 | D14: ='16''-25'' 10Ks'!D201 -> 0.036013057 | E14: ='16''-25'' 10Ks'!E201 -> 0.0332 | F14: ='16''-25'' 10Ks'!F201 -> 0.0448 | G14: ='16''-25'' 10Ks'!G201 -> 0.0316 | H14: ='16''-25'' 10Ks'!H201 -> 0.025709788 | I14: ='16''-25'' 10Ks'!I201 -> 0.023 | J14: ='16''-25'' 10Ks'!J201 -> 0.0357 | ... L14: ='16''-25'' 10Ks'!L201 -> 0.0393 | M14: 0.043 | N14: 0.045 | O14: 0.047 | P14: 0.048 | Q14: 0.05 | R14: 0.05 | S14: 0.05 | T14: 0.05 | U14: 0.05 | V14: 0.05
B15: Dividend growth % | D15: =D41/C41-1 -> 0.14454094 | E15: =E41/D41-1 -> 0.13875339 | F15: =F41/E41-1 -> 0.14612089 | G15: =G41/F41-1 -> 0.1391196 | H15: =H41/G41-1 -> 0.10244258 | I15: =I41/H41-1 -> 0.10846561 | J15: =J41/I41-1 -> 0.12828162 | K15: =K41/J41-1 -> 0.1197779 | L15: =L41/K41-1 -> 0.10507674 | M15: ='DDM Model'!C20 -> 0.1001 | N15: ='DDM Model'!D20 -> 0.06 | O15: ='DDM Model'!E20 -> 0.06 | P15: ='DDM Model'!F20 -> 0.055714286 | Q15: ='DDM Model'!G20 -> 0.051428571 | R15: ='DDM Model'!H20 -> 0.047142857 | S15: ='DDM Model'!I20 -> 0.042857143 | T15: ='DDM Model'!J20 -> 0.038571429 | ... V15: ='DDM Model'!L20 -> 0.03
B17: Income Statement
B18: Operating revenues | C18: ='16''-25'' 10Ks'!C8 -> 16138 | D18: ='16''-25'' 10Ks'!D8 -> 17173 | E18: ='16''-25'' 10Ks'!E8 -> 16727 | F18: ='16''-25'' 10Ks'!F8 -> 19204 | G18: ='16''-25'' 10Ks'!G8 -> 17997 | H18: ='16''-25'' 10Ks'!H8 -> 17069 | I18: ='16''-25'' 10Ks'!I8 -> 20956 | J18: ='16''-25'' 10Ks'!J8 -> 28114 | ... L18: ='16''-25'' 10Ks'!L8 -> 27412 | M18: =L18*(1+M7) -> 30153.2 | N18: =M18*(1+N7) -> 33168.52 | O18: =N18*(1+O7) -> 36419.035 | P18: =O18*(1+P7) -> 39878.843 | Q18: =P18*(1+Q7) -> 43587.576 | R18: =Q18*(1+R7) -> 47597.633 | S18: =R18*(1+S7) -> 51929.017 | T18: =S18*(1+T7) -> 56602.629 | ... V18: =U18*(1+V7) -> 67249.583
B19: Cost of sales (fuel & purchased power) | C19: =-'16''-25'' 10Ks'!C11 -> -3992 | D19: =-'16''-25'' 10Ks'!D11 -> -4071 | E19: =-'16''-25'' 10Ks'!E11 -> -3732 | F19: =-'16''-25'' 10Ks'!F11 -> -4363 | G19: =-'16''-25'' 10Ks'!G11 -> -3539 | H19: =-'16''-25'' 10Ks'!H11 -> -4527 | I19: =-'16''-25'' 10Ks'!I11 -> -6389 | J19: =-'16''-25'' 10Ks'!J11 -> -5457 | ... L19: =-'16''-25'' 10Ks'!L11 -> -4944 | M19: =-M8*M18 -> -5427.576 | N19: =-N8*N18 -> -5970.3336 | O19: =-O8*O18 -> -6555.4263 | P19: =-P8*P18 -> -7178.1918 | Q19: =-Q8*Q18 -> -7845.7636 | R19: =-R8*R18 -> -8567.5739 | S19: =-S8*S18 -> -9347.2231 | T19: =-T8*T18 -> -10188.473 | ... V19: =-V8*V18 -> -12104.925
B20: Gross profit | C20: =C18+C19 -> 12146 | D20: =D18+D19 -> 13102 | E20: =E18+E19 -> 12995 | F20: =F18+F19 -> 14841 | G20: =G18+G19 -> 14458 | H20: =H18+H19 -> 12542 | I20: =I18+I19 -> 14567 | J20: =J18+J19 -> 22657 | ... V20: =V18+V19 -> 55144.658
B21: Operating & other expenses | C21: =-'16''-25'' 10Ks'!C12-'16''-25'' 10Ks'!C14+'16''-25'' 10Ks'!C16 -> -4567 | D21: =-'16''-25'' 10Ks'!D12-'16''-25'' 10Ks'!D14+'16''-25'' 10Ks'!D16 -> -5572 | E21: =-'16''-25'' 10Ks'!E12-'16''-25'' 10Ks'!E14+'16''-25'' 10Ks'!E16 -> -4804 | F21: =-'16''-25'' 10Ks'!F12-'16''-25'' 10Ks'!F14+'16''-25'' 10Ks'!F16 -> -5272 | G21: =-'16''-25'' 10Ks'!G12-'16''-25'' 10Ks'!G14+'16''-25'' 10Ks'!G16 -> -5290 | H21: =-'16''-25'' 10Ks'!H12-'16''-25'' 10Ks'!H14+'16''-25'' 10Ks'!H16 -> -5705 | I21: =-'16''-25'' 10Ks'!I12-'16''-25'' 10Ks'!I14+'16''-25'' 10Ks'!I16 -> -5983 | J21: =-'16''-25'' 10Ks'!J12-'16''-25'' 10Ks'!J14+'16''-25'' 10Ks'!J16 -> -6541 | ... L21: =-'16''-25'' 10Ks'!L12-'16''-25'' 10Ks'!L14+'16''-25'' 10Ks'!L16 -> -7608 | M21: =-M9*M18 -> -8352.4364 | N21: =-N9*N18 -> -9187.68 | O21: =-O9*O18 -> -10088.073 | P21: =-P9*P18 -> -11046.44 | Q21: =-Q9*Q18 -> -12073.758 | R21: =-R9*R18 -> -13184.544 | S21: =-S9*S18 -> -14384.338 | T21: =-T9*T18 -> -15678.928 | ... V21: =-V9*V18 -> -18628.135
B22: EBITDA | C22: =C20+C21 -> 7579 | D22: =D20+D21 -> 7530 | E22: =E20+E21 -> 8191 | F22: =F20+F21 -> 9569 | G22: =G20+G21 -> 9168 | H22: =H20+H21 -> 6837 | I22: =I20+I21 -> 8584 | J22: =J20+J21 -> 16116 | ... V22: =V20+V21 -> 36516.524
B23: Depreciation & amortization | C23: =-'16''-25'' 10Ks'!C13 -> -3120 | D23: =-'16''-25'' 10Ks'!D13 -> -2357 | E23: =-'16''-25'' 10Ks'!E13 -> -3911 | F23: =-'16''-25'' 10Ks'!F13 -> -4216 | G23: =-'16''-25'' 10Ks'!G13 -> -4052 | H23: =-'16''-25'' 10Ks'!H13 -> -3924 | I23: =-'16''-25'' 10Ks'!I13 -> -4503 | J23: =-'16''-25'' 10Ks'!J13 -> -5879 | ... L23: =-'16''-25'' 10Ks'!L13 -> -6580 | M23: =-M11*L46 -> -6560.274 | N23: =-N11*M46 -> -7460.7408 | O23: =-O11*N46 -> -8428.3944 | P23: =-P11*O46 -> -9436.9232 | Q23: =-Q11*P46 -> -10486.942 | R23: =-R11*Q46 -> -11559.894 | S23: =-S11*R46 -> -12661.005 | T23: =-T11*S46 -> -13753.403 | ... V23: =-V11*U46 -> -15761.051
B24: EBIT (operating income) | C24: =C22+C23 -> 4459 | D24: =D22+D23 -> 5173 | E24: =E22+E23 -> 4280 | F24: =F22+F23 -> 5353 | G24: =G22+G23 -> 5116 | H24: =H22+H23 -> 2913 | I24: =I22+I23 -> 4081 | J24: =J22+J23 -> 10237 | ... V24: =V22+V23 -> 20755.472
B25: Interest & other, net | C25: ='16''-25'' 10Ks'!C29-C24 -> -81 | D25: ='16''-25'' 10Ks'!D29-D24 -> -510 | E25: ='16''-25'' 10Ks'!E29-E24 -> 3072 | F25: ='16''-25'' 10Ks'!F29-F24 -> -1517 | G25: ='16''-25'' 10Ks'!G29-G24 -> -2703 | H25: ='16''-25'' 10Ks'!H29-H24 -> 262 | I25: ='16''-25'' 10Ks'!I29-I24 -> -249 | J25: ='16''-25'' 10Ks'!J29-J24 -> -2949 | ... L25: ='16''-25'' 10Ks'!L29-L24 -> -3750 | M25: =-M14*L51+M10*M18 -> -3207.021 | N25: =-N14*M51+N10*N18 -> -4044.5641 | O25: =-O14*N51+O10*O18 -> -4687.9919 | P25: =-P14*O51+P10*P18 -> -5276.3285 | Q25: =-Q14*P51+Q10*Q18 -> -6065.7889 | R25: =-R14*Q51+R10*R18 -> -6621.9147 | S25: =-S14*R51+S10*S18 -> -7223.3586 | T25: =-T14*S51+T10*T18 -> -7873.142 | ... V25: =-V14*U51+V10*V18 -> -9335.2697
B26: Income before taxes (EBT) | C26: =C24+C25 -> 4378 | D26: =D24+D25 -> 4663 | E26: =E24+E25 -> 7352 | F26: =F24+F25 -> 3836 | G26: =G24+G25 -> 2413 | H26: =H24+H25 -> 3175 | I26: =I24+I25 -> 3832 | J26: =J24+J25 -> 7288 | ... V26: =V24+V25 -> 11420.203
B27: Income tax (benefit) | C27: =-'16''-25'' 10Ks'!C30 -> -1379 | D27: =-'16''-25'' 10Ks'!D30 -> 660 | E27: =-'16''-25'' 10Ks'!E30 -> -1576 | F27: =-'16''-25'' 10Ks'!F30 -> -448 | G27: =-'16''-25'' 10Ks'!G30 -> -44 | H27: =-'16''-25'' 10Ks'!H30 -> -348 | I27: =-'16''-25'' 10Ks'!I30 -> -586 | J27: =-'16''-25'' 10Ks'!J30 -> -1006 | ... L27: =-'16''-25'' 10Ks'!L30 -> 802 | M27: =-M12*M26 -> -396.35356 | N27: =-N12*N26 -> -455.3641 | O27: =-O12*O26 -> -532.73197 | P27: =-P12*P26 -> -624.68642 | Q27: =-Q12*Q26 -> -711.53226 | R27: =-R12*R26 -> -766.37059 | S27: =-S12*S26 -> -831.30932 | T27: =-T12*T26 -> -910.86821 | ... V27: =-V12*V26 -> -1142.0203
B28: Net income incl. NCI | C28: =C26+C27 -> 2999 | D28: =D26+D27 -> 5323 | E28: =E26+E27 -> 5776 | F28: =F26+F27 -> 3388 | G28: =G26+G27 -> 2369 | H28: =H26+H27 -> 2827 | I28: =I26+I27 -> 3246 | J28: =J26+J27 -> 6282 | ... V28: =V26+V27 -> 10278.182
B29: Less: net loss to NCI | C29: ='16''-25'' 10Ks'!C32 -> -93 | D29: ='16''-25'' 10Ks'!D32 -> 57 | E29: ='16''-25'' 10Ks'!E32 -> 862 | F29: ='16''-25'' 10Ks'!F32 -> 381 | G29: ='16''-25'' 10Ks'!G32 -> 550 | H29: ='16''-25'' 10Ks'!H32 -> 746 | I29: ='16''-25'' 10Ks'!I32 -> 901 | J29: ='16''-25'' 10Ks'!J32 -> 1028 | ... L29: ='16''-25'' 10Ks'!L32 -> 1503 | M29: =L29 -> 1503 | N29: =M29 -> 1503 | O29: =N29 -> 1503 | P29: =O29 -> 1503 | Q29: =P29 -> 1503 | R29: =Q29 -> 1503 | S29: =R29 -> 1503 | T29: =S29 -> 1503 | ... V29: =U29 -> 1503
B30: Net income to NEE | C30: =C28+C29 -> 2906 | D30: =D28+D29 -> 5380 | E30: =E28+E29 -> 6638 | F30: =F28+F29 -> 3769 | G30: =G28+G29 -> 2919 | H30: =H28+H29 -> 3573 | I30: =I28+I29 -> 4147 | J30: =J28+J29 -> 7310 | ... V30: =V28+V29 -> 11781.182
B32: Cash Flow Statement
B33: Net income (to NEE) | C33: =C30 -> 2906 | D33: =D30 -> 5380 | E33: =E30 -> 6638 | F33: =F30 -> 3769 | G33: =G30 -> 2919 | H33: =H30 -> 3573 | I33: =I30 -> 4147 | J33: =J30 -> 7310 | ... V33: =V30 -> 11781.182
B34: Add: depreciation & amortization | C34: =-C23 -> 3120 | D34: =-D23 -> 2357 | E34: =-E23 -> 3911 | F34: =-F23 -> 4216 | G34: =-G23 -> 4052 | H34: =-H23 -> 3924 | I34: =-I23 -> 4503 | J34: =-J23 -> 5879 | ... V34: =-V23 -> 15761.051
B35: Change in working capital | D35: =D68 -> -2586 | E35: =E68 -> -13600 | F35: =F68 -> 2820 | G35: =G68 -> 1221 | H35: =H68 -> -152 | I35: =I68 -> -368 | J35: =J68 -> -1881 | K35: =K68 -> 59 | ... V35: =V68 -> -625.72397
B36: Cash from operations | C36: =SUM(C33:C35) -> 6026 | D36: =SUM(D33:D35) -> 5151 | E36: =SUM(E33:E35) -> -3051 | F36: =SUM(F33:F35) -> 10805 | G36: =SUM(G33:G35) -> 8192 | H36: =SUM(H33:H35) -> 7345 | I36: =SUM(I33:I35) -> 8282 | J36: =SUM(J33:J35) -> 11308 | ... V36: =SUM(V33:V35) -> 26916.51
B37: Capital expenditure | C37: =-C60 -> -9636 | D37: =-D60 -> -10740 | E37: =-E60 -> -13004 | F37: =-F60 -> -17462 | G37: =-G60 -> -14610 | H37: =-H60 -> -16077 | I37: =-I60 -> -19283 | J37: =-J60 -> -25113 | ... V37: =-V60 -> -37767.366
B38: Cash from investing | C38: =C37 -> -9636 | D38: =D37 -> -10740 | E38: =E37 -> -13004 | F38: =F37 -> -17462 | G38: =G37 -> -14610 | H38: =H37 -> -16077 | I38: =I37 -> -19283 | J38: =J37 -> -25113 | ... V38: =V37 -> -37767.366
B39: Net debt issuance (retirement) | D39: =D72 -> 4185 | E39: =E72 -> 2687 | F39: =F72 -> 4871 | G39: =G72 -> 5508 | H39: =H72 -> 6736 | I39: =I72 -> 10139 | J39: =J72 -> 8245 | K39: =K72 -> 9122 | ... V39: =V72 -> 20254.96
B40: Equity issuance | C40: ='16''-25'' 10Ks'!C80 -> 537 | D40: ='16''-25'' 10Ks'!D80 -> 603 | E40: ='16''-25'' 10Ks'!E80 -> 718 | F40: ='16''-25'' 10Ks'!F80 -> 1494 | G40: ='16''-25'' 10Ks'!G80 -> -92 | H40: ='16''-25'' 10Ks'!H80 -> 14 | I40: ='16''-25'' 10Ks'!I80 -> 1460 | J40: ='16''-25'' 10Ks'!J80 -> 4514 | ... L40: ='16''-25'' 10Ks'!L80 -> 2038 | M40: 2000 | N40: =N60-N36-N72-N41 -> 10284.549 | O40: =O60-O36-O72-O41 -> 10677.199 | P40: =P60-P36-P72-P41 -> 11057.636 | Q40: =Q60-Q36-Q72-Q41 -> 10950.255 | R40: =R60-R36-R72-R41 -> 10364.669 | S40: =S60-S36-S72-S41 -> 8725.0498 | T40: =T60-T36-T72-T41 -> 5699.2216 | U40: =U60-U36-U72-U41 -> 2056.4855 | V40: =V60-V36-V72-V41 -> -1645.9067
B41: Dividends paid | C41: ='16''-25'' 10Ks'!C82 -> -1612 | D41: ='16''-25'' 10Ks'!D82 -> -1845 | E41: ='16''-25'' 10Ks'!E82 -> -2101 | F41: ='16''-25'' 10Ks'!F82 -> -2408 | G41: ='16''-25'' 10Ks'!G82 -> -2743 | H41: ='16''-25'' 10Ks'!H82 -> -3024 | I41: ='16''-25'' 10Ks'!I82 -> -3352 | J41: ='16''-25'' 10Ks'!J82 -> -3782 | ... L41: ='16''-25'' 10Ks'!L82 -> -4680 | M41: =L41*(1+M15) -> -5148.468 | N41: =M41*(1+N15) -> -5457.3761 | O41: =N41*(1+O15) -> -5784.8186 | P41: =O41*(1+P15) -> -6107.1157 | Q41: =P41*(1+Q15) -> -6421.1959 | R41: =Q41*(1+R15) -> -6723.9094 | S41: =R41*(1+S15) -> -7012.077 | T41: =S41*(1+T15) -> -7282.5428 | ... V41: =U41*(1+V15) -> -7758.1969
B42: Cash from financing | C42: =SUM(C39:C41) -> -1075 | D42: =SUM(D39:D41) -> 2943 | E42: =SUM(E39:E41) -> 1304 | F42: =SUM(F39:F41) -> 3957 | G42: =SUM(G39:G41) -> 2673 | H42: =SUM(H39:H41) -> 3726 | I42: =SUM(I39:I41) -> 8247 | J42: =SUM(J39:J41) -> 8977 | ... V42: =SUM(V39:V41) -> 10850.856
B43: Net change in cash | C43: =C36+C38+C42 -> -4685 | D43: =D36+D38+D42 -> -2646 | E43: =E36+E38+E42 -> -14751 | F43: =F36+F38+F42 -> -2700 | G43: =G36+G38+G42 -> -3745 | H43: =H36+H38+H42 -> -5006 | I43: =I36+I38+I42 -> -2754 | J43: =J36+J38+J42 -> -4828 | ... V43: =V36+V38+V42 -> 0
B45: Balance Sheet
...

Sheet DDM Model
B2: DDM Model — NextEra Energy, Inc. (NEE)
B3: Valuation Date: 08/03/2026
B5: Cost of Equity (CAPM)
B6: Risk-free rate | D6: 0.04652
B7: Equity risk premium | D7: 0.0446
B8: Levered beta | D8: ='DDM Assumptions'!D54 -> 0.42672131
B9: Cost of equity (rf + β × ERP) | D9: =D6+D8*D7 -> 0.06555177
B11: Dividend & Valuation Inputs
B12: Base-year dividend/share (2025A) | D12: 2.27
B13: Current share price ($) | D13: 86.55
B14: Valuation date | D14: 46237
B15: Terminal g rate | D15: 0.03
B17: Dividend Forecast & Discounting
B18: Forecast year | C18: 2026 | D18: 2027 | E18: 2028 | F18: 2029 | G18: 2030 | H18: 2031 | I18: 2032 | J18: 2033 | K18: 2034 | L18: 2035
B19: Discount period (t) | C19: 1 | D19: =C19+1 -> 2 | E19: =D19+1 -> 3 | F19: =E19+1 -> 4 | G19: =F19+1 -> 5 | H19: =G19+1 -> 6 | I19: =H19+1 -> 7 | J19: =I19+1 -> 8 | K19: =J19+1 -> 9 | L19: =K19+1 -> 10
B20: Dividend growth rate | C20: 0.1001 | D20: 0.06 | E20: 0.06 | F20: 0.055714286 | G20: 0.051428571 | H20: 0.047142857 | I20: 0.042857143 | J20: 0.038571429 | K20: 0.034285714 | L20: 0.03
B21: Dividend per share (DPS) | C21: =$D$12*(1+C20) -> 2.497227 | D21: =C21*(1+D20) -> 2.6470606 | E21: =D21*(1+E20) -> 2.8058843 | F21: =E21*(1+F20) -> 2.9622121 | G21: =F21*(1+G20) -> 3.1145544 | H21: =G21*(1+H20) -> 3.2613834 | I21: =H21*(1+I20) -> 3.401157 | J21: =I21*(1+J20) -> 3.5323445 | K21: =J21*(1+K20) -> 3.6534534 | L21: =K21*(1+L20) -> 3.763057
B22: Discount factor @ Ke | C22: =IFERROR(1/(1+$D$9)^C19,"") -> 0.93848091 | D22: =IFERROR(1/(1+$D$9)^D19,"") -> 0.88074643 | E22: =IFERROR(1/(1+$D$9)^E19,"") -> 0.82656371 | F22: =IFERROR(1/(1+$D$9)^F19,"") -> 0.77571427 | G22: =IFERROR(1/(1+$D$9)^G19,"") -> 0.72799304 | H22: =IFERROR(1/(1+$D$9)^H19,"") -> 0.68320757 | I22: =IFERROR(1/(1+$D$9)^I19,"") -> 0.64117727 | J22: =IFERROR(1/(1+$D$9)^J19,"") -> 0.60173263 | ... L22: =IFERROR(1/(1+$D$9)^L19,"") -> 0.52997386
B23: PV of dividend | C23: =IFERROR(C21*C22,"") -> 2.3435999 | D23: =IFERROR(D21*D22,"") -> 2.3313892 | E23: =IFERROR(E21*E22,"") -> 2.3192421 | F23: =IFERROR(F21*F22,"") -> 2.2978302 | G23: =IFERROR(G21*G22,"") -> 2.2673739 | H23: =IFERROR(H21*H22,"") -> 2.2282018 | I23: =IFERROR(I21*I22,"") -> 2.1807445 | J23: =IFERROR(J21*J22,"") -> 2.1255269 | ... L23: =IFERROR(L21*L22,"") -> 1.9943219
B25: Terminal Value (Gordon growth on 2035 DPS)
B26: Terminal-year DPS (2035) | D26: =L21 -> 3.763057
B27: Terminal value @ 2035 = DPS×(1+g)/(Ke−g) | D27: =IFERROR(L21*(1+$D$15)/($D$9-$D$15),0) -> 109.02266
B28: PV of terminal value | D28: =IFERROR(D27*L22,0) -> 57.779163
B30: Intrinsic Value per Share
B31: PV of explicit dividends (2026–2035) | D31: =SUM(C23:L23) -> 22.151389
B32: Plus: PV of terminal value | D32: =D28 -> 57.779163
B33: Intrinsic value per share | D33: =D31+D32 -> 79.930552
B34: Current share price | D34: =D13 -> 86.55
B35: Implied upside / (downside) | D35: =IFERROR(D33/D13-1,"") -> -0.076481206
B37: Consistency Checks
B38: Assumed dividend growth (input) | C38: =C20 -> 0.1001 | D38: =D20 -> 0.06 | E38: =E20 -> 0.06 | F38: =F20 -> 0.055714286 | G38: =G20 -> 0.051428571 | H38: =H20 -> 0.047142857 | I38: =I20 -> 0.042857143 | J38: =J20 -> 0.038571429 | ... L38: =L20 -> 0.03
B39: Adjusted EPS growth | C39: ='Residual Income Model'!C18 -> 0.078171489 | D39: ='Residual Income Model'!D18 -> 0.078703176 | E39: ='Residual Income Model'!E18 -> 0.079262967 | F39: ='Residual Income Model'!F18 -> 0.07897061 | G39: ='Residual Income Model'!G18 -> 0.078853512 | H39: ='Residual Income Model'!H18 -> 0.079389031 | I39: ='Residual Income Model'!I18 -> 0.0786122 | J39: ='Residual Income Model'!J18 -> 0.060431955 | ... L39: ='Residual Income Model'!L18 -> 0.035331789
B40: Implied payout ratio (DPS ÷ adj EPS) | C40: =C21/'Residual Income Model'!C17 -> 0.62430422 | D40: =D21/'Residual Income Model'!D17 -> 0.61347967 | E40: =E21/'Residual Income Model'!E17 -> 0.60253013 | F40: =F21/'Residual Income Model'!F17 -> 0.58954309 | G40: =G21/'Residual Income Model'!G17 -> 0.57455664 | H40: =H21/'Residual Income Model'!H17 -> 0.55739206 | I40: =I21/'Residual Income Model'!I17 -> 0.538915 | J40: =J21/'Residual Income Model'!J17 -> 0.52780541 | ... L40: =L21/'Residual Income Model'!L17 -> 0.51736451

Sheet Residual Income Model
B2: Residual Income Model — NextEra Energy, Inc. (NEE)
B3: Valuation Date: 08/03/2026
B5: Inputs
B6: Cost of equity (Ke) | D6: ='DDM Model'!D9 -> 0.06555177
B7: Current book value / share | D7: ='3-Statement Model'!L53/'SOTP & Multiples'!C17 -> 26.367938
B8: Terminal residual-income growth (g∞) | D8: 0.03
B9: Book-value growth (rate base–funded) | C9: =C21/C15-1 -> 0.080127206 | D9: =D21/D15-1 -> 0.079975822 | E9: =E21/E15-1 -> 0.079683744 | F9: =F21/F15-1 -> 0.07956704 | G9: =G21/G15-1 -> 0.079389031 | H9: =H21/H15-1 -> 0.07932604 | I9: =I21/I15-1 -> 0.079725529 | J9: =J21/J15-1 -> 0.078056329 | ... L9: =L21/L15-1 -> 0.071724401
B12: Residual Income Forecast
B13: Forecast year | C13: 2026 | D13: 2027 | E13: 2028 | F13: 2029 | G13: 2030 | H13: 2031 | I13: 2032 | J13: 2033 | K13: 2034 | L13: 2035
B14: Discount period (t) | C14: 1 | D14: =C14+1 -> 2 | E14: =D14+1 -> 3 | F14: =E14+1 -> 4 | G14: =F14+1 -> 5 | H14: =G14+1 -> 6 | I14: =H14+1 -> 7 | J14: =I14+1 -> 8 | K14: =J14+1 -> 9 | L14: =K14+1 -> 10
B15: Beginning book value / share | C15: =D7 -> 26.367938 | D15: =C21 -> 28.480727 | E15: =D21 -> 30.758497 | F15: =E21 -> 33.209449 | G15: =F21 -> 35.851827 | H15: =G21 -> 38.698069 | I15: =H21 -> 41.767833 | J15: =I21 -> 45.097796 | K15: =J21 -> 48.617964 | L15: =K21 -> 52.289806
B16: Forecast ROE | C16: 0.1517 | D16: 0.1515 | E16: 0.1514 | F16: 0.1513 | G16: 0.1512 | H16: 0.1512 | I16: 0.1511 | J16: 0.1484 | K16: 0.1445 | L16: 0.1391
B17: EPS = ROE × beginning BV | C17: =C16*C15 -> 4.0000162 | D17: =D16*D15 -> 4.3148302 | E17: =E16*E15 -> 4.6568364 | F17: =F16*F15 -> 5.0245897 | G17: =G16*G15 -> 5.4207962 | H17: =H16*H15 -> 5.851148 | I17: =I16*I15 -> 6.3111196 | J17: =J16*J15 -> 6.6925129 | ... L17: =L16*L15 -> 7.2735121
B18: EPS growth (y/y) | C18: =C17/3.71-1 -> 0.078171489 | D18: =D17/C17-1 -> 0.078703176 | E18: =E17/D17-1 -> 0.079262967 | F18: =F17/E17-1 -> 0.07897061 | G18: =G17/F17-1 -> 0.078853512 | H18: =H17/G17-1 -> 0.079389031 | I18: =I17/H17-1 -> 0.0786122 | J18: =J17/I17-1 -> 0.060431955 | K18: =K17/J17-1 -> 0.04972466 | L18: =L17/K17-1 -> 0.035331789
B19: Dividends / share (DPS) | C19: ='DDM Model'!C21 -> 2.497227 | D19: ='DDM Model'!D21 -> 2.6470606 | E19: ='DDM Model'!E21 -> 2.8058843 | F19: ='DDM Model'!F21 -> 2.9622121 | G19: ='DDM Model'!G21 -> 3.1145544 | H19: ='DDM Model'!H21 -> 3.2613834 | I19: ='DDM Model'!I21 -> 3.401157 | J19: ='DDM Model'!J21 -> 3.5323445 | ... L19: ='DDM Model'!L21 -> 3.763057
B20: Net equity issued / share | C20: 0.61 | D20: 0.61 | E20: 0.6 | F20: 0.58 | G20: 0.54 | H20: 0.48 | I20: 0.42 | J20: 0.36 | K20: 0.3 | L20: 0.24
B21: Ending book value / share = beg + EPS − DPS + issued | C21: =C15+(C17-C19)+C20 -> 28.480727 | D21: =D15+(D17-D19)+D20 -> 30.758497 | E21: =E15+(E17-E19)+E20 -> 33.209449 | F21: =F15+(F17-F19)+F20 -> 35.851827 | G21: =G15+(G17-G19)+G20 -> 38.698069 | H21: =H15+(H17-H19)+H20 -> 41.767833 | I21: =I15+(I17-I19)+I20 -> 45.097796 | J21: =J15+(J17-J19)+J20 -> 48.617964 | ... L21: =L15+(L17-L19)+L20 -> 56.040261
B22: Equity charge = Ke × beginning BV | C22: =$D$6*C15 -> 1.728465 | D22: =$D$6*D15 -> 1.8669621 | E22: =$D$6*E15 -> 2.0162739 | F22: =$D$6*F15 -> 2.1769382 | G22: =$D$6*G15 -> 2.3501507 | H22: =$D$6*H15 -> 2.5367269 | I22: =$D$6*I15 -> 2.7379554 | J22: =$D$6*J15 -> 2.9562403 | ... L22: =$D$6*L15 -> 3.4276894
B23: Residual income = EPS − equity charge | C23: =C17-C22 -> 2.2715512 | D23: =D17-D22 -> 2.4478681 | E23: =E17-E22 -> 2.6405625 | F23: =F17-F22 -> 2.8476515 | G23: =G17-G22 -> 3.0706455 | H23: =H17-H22 -> 3.3144211 | I23: =I17-I22 -> 3.5731642 | J23: =J17-J22 -> 3.7362725 | ... L23: =L17-L22 -> 3.8458227
B24: Discount factor @ Ke | C24: =IFERROR(1/(1+$D$6)^C14,"") -> 0.93848091 | D24: =IFERROR(1/(1+$D$6)^D14,"") -> 0.88074643 | E24: =IFERROR(1/(1+$D$6)^E14,"") -> 0.82656371 | F24: =IFERROR(1/(1+$D$6)^F14,"") -> 0.77571427 | G24: =IFERROR(1/(1+$D$6)^G14,"") -> 0.72799304 | H24: =IFERROR(1/(1+$D$6)^H14,"") -> 0.68320757 | I24: =IFERROR(1/(1+$D$6)^I14,"") -> 0.64117727 | J24: =IFERROR(1/(1+$D$6)^J14,"") -> 0.60173263 | ... L24: =IFERROR(1/(1+$D$6)^L14,"") -> 0.52997386
B25: PV of residual income | C25: =IFERROR(C23*C24,"") -> 2.1318074 | D25: =IFERROR(D23*D24,"") -> 2.1559511 | E25: =IFERROR(E23*E24,"") -> 2.1825932 | F25: =IFERROR(F23*F24,"") -> 2.2089639 | G25: =IFERROR(G23*G24,"") -> 2.2354085 | H25: =IFERROR(H23*H24,"") -> 2.2644376 | I25: =IFERROR(I23*I24,"") -> 2.2910316 | J25: =IFERROR(J23*J24,"") -> 2.2482371 | ... L25: =IFERROR(L23*L24,"") -> 2.0381855
B27: Intrinsic Value per Share
B28: Current book value / share (B0) | D28: =D7 -> 26.367938
B29: PV of explicit residual income (2026–2035) | D29: =SUM(C25:L25) -> 21.924161
B30: Terminal value of residual income (@2035) | D30: =IFERROR(L23*(1+$D$8)/($D$6-$D$8),0) -> 111.42054
B31: PV of terminal residual income | D31: =IFERROR(D30*L24,0) -> 59.049972
B32: Intrinsic value / share = B0 + PV RI + PV terminal | D32: =D28+D29+D31 -> 107.34207
B33: Current share price | D33: ='DDM Model'!D13 -> 86.55
B34: Implied upside / (downside) | D34: =IFERROR(D32/D33-1,"") -> 0.24023191
B36: Consistency Checks
B37: Assumed ROE (input) | C37: =C16 -> 0.1517 | D37: =D16 -> 0.1515 | E37: =E16 -> 0.1514 | F37: =F16 -> 0.1513 | G37: =G16 -> 0.1512 | H37: =H16 -> 0.1512 | I37: =I16 -> 0.1511 | J37: =J16 -> 0.1484 | ... L37: =L16 -> 0.1391
B38: Implied ROE — 3-statement (GAAP, NI ÷ avg equity) | C38: ='3-Statement Model'!M30/(('3-Statement Model'!L53+'3-Statement Model'!M53)/2) -> 0.13556924 | D38: ='3-Statement Model'!N30/(('3-Statement Model'!M53+'3-Statement Model'!N53)/2) -> 0.122373 | E38: ='3-Statement Model'!O30/(('3-Statement Model'!N53+'3-Statement Model'!O53)/2) -> 0.11440151 | F38: ='3-Statement Model'!P30/(('3-Statement Model'!O53+'3-Statement Model'!P53)/2) -> 0.10940912 | G38: ='3-Statement Model'!Q30/(('3-Statement Model'!P53+'3-Statement Model'!Q53)/2) -> 0.10394496 | H38: ='3-Statement Model'!R30/(('3-Statement Model'!Q53+'3-Statement Model'!R53)/2) -> 0.10416037 | I38: ='3-Statement Model'!S30/(('3-Statement Model'!R53+'3-Statement Model'!S53)/2) -> 0.1051188 | J38: ='3-Statement Model'!T30/(('3-Statement Model'!S53+'3-Statement Model'!T53)/2) -> 0.10699252 | ... L38: ='3-Statement Model'!V30/(('3-Statement Model'!U53+'3-Statement Model'!V53)/2) -> 0.11439603
B39: Normalization premium (adjusted − GAAP) | C39: =C37-C38 -> 0.016130757 | D39: =D37-D38 -> 0.029127 | E39: =E37-E38 -> 0.036998487 | F39: =F37-F38 -> 0.041890882 | G39: =G37-G38 -> 0.04725504 | H39: =H37-H38 -> 0.047039634 | I39: =I37-I38 -> 0.045981199 | J39: =J37-J38 -> 0.041407482 | ... L39: =L37-L38 -> 0.024703971

Sheet SOTP & Multiples
B2: NextEra Energy — Sum-of-the-Parts Relative Valuation
B3: All data as of 4:00pm EDT, 8/3/2026
B5: NEE SEGMENT FINANCIALS (FY2025, $mm)
B6: Metric | C6: FPL | D6: NEER
B7: Net income to NEE (GAAP) | C7: 5012 | D7: 2975
B8: Net income (adjusted) | C8: 5012 | D8: 3523
B9: Operating income (EBIT) | C9: 6819 | D9: 1509
B10: D&A | C10: 3778 | D10: 2738
B11: EBITDA (GAAP) | C11: =C9+C10 -> 10597 | D11: =D9+D10 -> 4247
B12: EBITDA (adjusted, mgmt) | C12: =C11 -> 10597 | D12: 11196
B13: Book equity (to NEE) | C13: 46986 | D13: ='16''-25'' 10Ks'!L142-C13 -> 7622
B14: Total debt | C14: 29812 | D14: ='16''-25'' 10Ks'!L188-C14 -> 65807
B15: Cash | C15: 42 | D15: ='16''-25'' 10Ks'!L94-C15 -> 2770
B16: Net debt | C16: =C14-C15 -> 29770 | D16: =D14-D15 -> 63037
B17: NEE diluted shares (mm) | C17: 2071
B18: NEE share price ($) | C18: ='DDM Model'!D13 -> 86.55
B20: FPL PEERS (regulated)
B21: Ticker | C21: Curr | D21: Price* | E21: P/E* | F21: EBITDA | G21: Net debt | H21: Book eq | I21: Shares mm | J21: DPS | K21: Mkt cap | L21: EV | M21: EV/EBITDA | N21: P/B | O21: Div yld | P21: EPS FY25 | Q21: NCI+pref
B22: DTE | C22: USD | D22: 141.72 | E22: =IFERROR(D22/P22,"") -> 20.159971 | F22: 3214 | G22: 23766 | H22: 12303 | I22: 207.745 | J22: 4.44 | K22: =IFERROR(D22*I22,"") -> 29441.621 | L22: =IFERROR(K22+G22+Q22,"") -> 53212.621 | M22: =IFERROR(L22/F22,"") -> 16.556509 | N22: =IFERROR(K22/H22,"") -> 2.3930441 | O22: =IFERROR(J22/D22,"") -> 0.031329382 | P22: =1460.4/I22 -> 7.0297721 | Q22: 5
B23: CMS | C23: USD | D23: 71.74 | E23: =IFERROR(D23/P23,"") -> 20.322796 | F23: 3033 | G23: 18389 | H23: 8920 | I23: 306.4 | J23: 2.17 | K23: =IFERROR(D23*I23,"") -> 21981.136 | L23: =IFERROR(K23+G23+Q23,"") -> 41161.136 | M23: =IFERROR(L23/F23,"") -> 13.571097 | N23: =IFERROR(K23/H23,"") -> 2.4642529 | O23: =IFERROR(J23/D23,"") -> 0.030248118 | P23: =1081.6/I23 -> 3.5300261 | Q23: 791
B24: EVRG | C24: USD | D24: 83.23 | E24: =IFERROR(D24/P24,"") -> 22.739427 | F24: 2696 | G24: 14780 | H24: 10221 | I24: 230.263 | J24: 2.48 | K24: =IFERROR(D24*I24,"") -> 19164.789 | L24: =IFERROR(K24+G24+Q24,"") -> 33990.789 | M24: =IFERROR(L24/F24,"") -> 12.60786 | N24: =IFERROR(K24/H24,"") -> 1.8750406 | O24: =IFERROR(J24/D24,"") -> 0.029796948 | P24: =842.8/I24 -> 3.6601625 | Q24: 46
B25: DUK | C25: USD | D25: 124.28 | E25: =IFERROR(D25/P25,"") -> 19.695641 | F25: 13418 | G25: 89591 | H25: 50869 | I25: 778 | J25: 4.22 | K25: =IFERROR(D25*I25,"") -> 96689.84 | L25: =IFERROR(K25+G25+Q25,"") -> 188430.84 | M25: =IFERROR(L25/F25,"") -> 14.043139 | N25: =IFERROR(K25/H25,"") -> 1.9007616 | O25: =IFERROR(J25/D25,"") -> 0.033955584 | P25: =4909.2/I25 -> 6.3100257 | Q25: 2150
B26: PNW | C26: USD | D26: 100.81 | E26: =IFERROR(D26/P26,"") -> 19.96246 | F26: 1983 | G26: 10560 | H26: 7046 | I26: 120.951 | J26: 3.6 | K26: =IFERROR(D26*I26,"") -> 12193.07 | L26: =IFERROR(K26+G26+Q26,"") -> 22794.07 | M26: =IFERROR(L26/F26,"") -> 11.49474 | N26: =IFERROR(K26/H26,"") -> 1.7304954 | O26: =IFERROR(J26/D26,"") -> 0.035710743 | P26: =610.8/I26 -> 5.0499789 | Q26: 41
B27: ETR | C27: USD | D27: 108.06 | E27: =IFERROR(D27/P27,"") -> 27.637164 | F27: 5280 | G27: 29006 | H27: 16923 | I27: 583.204 | J27: 2.44 | K27: =IFERROR(D27*I27,"") -> 63021.024 | L27: =IFERROR(K27+G27+Q27,"") -> 92227.024 | M27: =IFERROR(L27/F27,"") -> 17.467239 | N27: =IFERROR(K27/H27,"") -> 3.7239865 | O27: =IFERROR(J27/D27,"") -> 0.022580048 | P27: =2280.3/I27 -> 3.9099526 | Q27: 200
B28: AEE | C28: USD | D28: 109.5 | E28: =IFERROR(D28/P28,"") -> 20.467843 | F28: 3594 | G28: 19817 | H28: 13401 | I28: 276.4 | J28: 2.84 | K28: =IFERROR(D28*I28,"") -> 30265.8 | L28: =IFERROR(K28+G28+Q28,"") -> 50211.8 | M28: =IFERROR(L28/F28,"") -> 13.971007 | N28: =IFERROR(K28/H28,"") -> 2.2584732 | O28: =IFERROR(J28/D28,"") -> 0.025936073 | P28: =1478.7/I28 -> 5.3498553 | Q28: 129
B29: XEL | C29: USD | D29: 77.69 | E29: =IFERROR(D29/P29,"") -> 21.28534 | F29: 5536 | G29: 33609 | H29: 23609 | I29: 623.601 | J29: 2.19 | K29: =IFERROR(D29*I29,"") -> 48447.562 | L29: =IFERROR(K29+G29+Q29,"") -> 82081.562 | M29: =IFERROR(L29/F29,"") -> 14.826872 | N29: =IFERROR(K29/H29,"") -> 2.0520802 | O29: =IFERROR(J29/D29,"") -> 0.028188956 | P29: =2276.1/I29 -> 3.64993 | Q29: 25
B30: SO | C30: USD | D30: 92.94 | E30: =IFERROR(D30/P30,"") -> 23.709184 | F30: 12786 | G30: 70952 | H30: 36016 | I30: 1100 | J30: 2.94 | K30: =IFERROR(D30*I30,"") -> 102234 | L30: =IFERROR(K30+G30+Q30,"") -> 176037 | M30: =IFERROR(L30/F30,"") -> 13.767949 | N30: =IFERROR(K30/H30,"") -> 2.8385717 | O30: =IFERROR(J30/D30,"") -> 0.031633312 | P30: =4312/I30 -> 3.92 | Q30: 2851
B31: LNT | C31: USD | D31: 71.27 | E31: =IFERROR(D31/P31,"") -> 22.698091 | F31: 1871 | G31: 11560 | H31: 7334 | I31: 257.141 | J31: 2.03 | K31: =IFERROR(D31*I31,"") -> 18326.439 | L31: =IFERROR(K31+G31+Q31,"") -> 29898.439 | M31: =IFERROR(L31/F31,"") -> 15.979925 | N31: =IFERROR(K31/H31,"") -> 2.4988327 | O31: =IFERROR(J31/D31,"") -> 0.028483233 | P31: =807.4/I31 -> 3.1399116 | Q31: 12
B32: Median | E32: =IFERROR(MEDIAN(E22:E31),"") -> 20.876592 | M32: =IFERROR(MEDIAN(M22:M31),"") -> 14.007073 | N32: =IFERROR(MEDIAN(N22:N31),"") -> 2.3257587 | O32: =IFERROR(MEDIAN(O22:O31),"") -> 0.030022533
B35: NEER PEERS (renewables / IPP)
B36: Ticker | C36: Curr | D36: Price* | E36: P/E* | F36: EBITDA | G36: Net debt | H36: Shares mm | I36: DPS | J36: Mkt cap | K36: EV | L36: EV/EBITDA | M36: Div yld | N36: EPS FY25 | O36: NCI+pref
B37: ENGI | C37: EUR | D37: 26.87 | E37: =IFERROR(D37/N37,"") -> 17.677421 | F37: 14732 | G37: 38902 | H37: 2435.3 | I37: 1.48 | J37: =IFERROR(D37*H37,"") -> 65436.511 | K37: =IFERROR(J37+G37+O37,"") -> 112217.51 | L37: =IFERROR(K37/F37,"") -> 7.6172625 | M37: =IFERROR(I37/D37,"") -> 0.055080015 | N37: =3701.7/H37 -> 1.5200181 | O37: 7879
B38: RWE | C38: EUR | D38: 65.69 | E38: =IFERROR(D38/N38,"") -> 15.276647 | F38: 5087 | G38: 10921 | H38: 727.6 | I38: 1.2 | J38: =IFERROR(D38*H38,"") -> 47796.044 | K38: =IFERROR(J38+G38+O38,"") -> 65900.044 | L38: =IFERROR(K38/F38,"") -> 12.954599 | M38: =IFERROR(I38/D38,"") -> 0.018267621 | N38: =3128.7/H38 -> 4.3000275 | O38: 7183
B39: AES | C39: USD | D39: 14.71 | E39: =IFERROR(D39/N39,"") -> 11.228791 | F39: 2871 | G39: 27636 | H39: 712.2 | I39: 0.69 | J39: =IFERROR(D39*H39,"") -> 10476.462 | K39: =IFERROR(J39+G39+O39,"") -> 43154.462 | L39: =IFERROR(K39/F39,"") -> 15.031161 | M39: =IFERROR(I39/D39,"") -> 0.046906866 | N39: =933/H39 -> 1.3100253 | O39: 5042
B40: IBE | C40: EUR | D40: 20.65 | E40: =IFERROR(D40/N40,"") -> 22.32436 | F40: 16592 | G40: 51755 | H40: 6681.2 | I40: 0.68 | J40: =IFERROR(D40*H40,"") -> 137966.78 | K40: =IFERROR(J40+G40+O40,"") -> 203072.78 | L40: =IFERROR(K40/F40,"") -> 12.239198 | M40: =IFERROR(I40/D40,"") -> 0.032929782 | N40: =6180.1/H40 -> 0.9249985 | O40: 13351
B41: EDPR | C41: EUR | D41: 13.52 | E41: NM | F41: 1974 | G41: 8100 | H41: 1168 | I41: 0.205 | J41: =IFERROR(D41*H41,"") -> 15791.36 | K41: =IFERROR(J41+G41+O41,"") -> 26791.36 | L41: =IFERROR(K41/F41,"") -> 13.572118 | M41: =IFERROR(I41/D41,"") -> 0.015162722 | N41: NM | O41: 2900
B42: SSE | C42: GBP | D42: 31.55 | E42: =IFERROR(D42/N42,"") -> 20.553617 | F42: 3208 | G42: 10095 | H42: 1145.4 | I42: 0.687 | J42: =IFERROR(D42*H42,"") -> 36137.37 | K42: =IFERROR(J42+G42+O42,"") -> 47932.37 | L42: =IFERROR(K42/F42,"") -> 14.941512 | M42: =IFERROR(I42/D42,"") -> 0.02177496 | N42: =1758.2/H42 -> 1.5350096 | O42: 1700
B43: BEP | C43: USD | D43: 33.68 | E43: NM | F43: 2698 | G43: 16800 | H43: 665.1 | I43: 1.49 | J43: =IFERROR(D43*H43,"") -> 22400.568 | K43: =IFERROR(J43+G43+O43,"") -> 39200.568 | L43: =IFERROR(K43/F43,"") -> 14.529491 | M43: =IFERROR(I43/D43,"") -> 0.044239905 | N43: NM | O43: 0
B44: CWEN | C44: USD | D44: 32.06 | E44: NM | F44: 1140 | G44: 8375 | H44: 120.9 | I44: 1.72 | J44: =IFERROR(D44*H44,"") -> 3876.054 | K44: =IFERROR(J44+G44+O44,"") -> 16138.054 | L44: =IFERROR(K44/F44,"") -> 14.156188 | M44: =IFERROR(I44/D44,"") -> 0.053649407 | N44: NM | O44: 3887
B45: NPI | C45: CAD | D45: 21.82 | E45: NM | F45: 1253 | G45: 5989 | H45: 261.3 | I45: 1.2 | J45: =IFERROR(D45*H45,"") -> 5701.566 | K45: =IFERROR(J45+G45+O45,"") -> 12053.566 | L45: =IFERROR(K45/F45,"") -> 9.6197654 | M45: =IFERROR(I45/D45,"") -> 0.054995417 | N45: NM | O45: 363
...

Sheet Operating Model
B2: Operating Model ($ in Millions, Normalized)
B3: Valuation Date: 08/03/2026
B4: NextEra Energy, Inc. - NYSE: NEE | C4: 2023A | D4: 2024A | E4: 2025A | F4: 2026E | G4: 2027E | H4: 2028E | I4: 2029E | J4: 2030E | K4: 2031E | L4: 2032E
B5: Revenue | C5: ='3-Statement Model'!J18 -> 28114 | D5: ='3-Statement Model'!K18 -> 24753 | E5: ='3-Statement Model'!L18 -> 27412 | F5: ='3-Statement Model'!M18 -> 30153.2 | G5: ='3-Statement Model'!N18 -> 33168.52 | H5: ='3-Statement Model'!O18 -> 36419.035 | I5: ='3-Statement Model'!P18 -> 39878.843 | J5: ='3-Statement Model'!Q18 -> 43587.576 | ... L5: ='3-Statement Model'!S18 -> 51929.017
B6: % Growth | C6: ='3-Statement Model'!J7 -> 0.34157282 | D6: ='3-Statement Model'!K7 -> -0.11954898 | E6: ='3-Statement Model'!L7 -> 0.10742132 | F6: ='3-Statement Model'!M7 -> 0.1 | G6: ='3-Statement Model'!N7 -> 0.1 | H6: ='3-Statement Model'!O7 -> 0.098 | I6: ='3-Statement Model'!P7 -> 0.095 | J6: ='3-Statement Model'!Q7 -> 0.093 | ... L6: ='3-Statement Model'!S7 -> 0.091
B8: EBITDA | C8: ='3-Statement Model'!J22 -> 16116 | D8: ='3-Statement Model'!K22 -> 12941 | E8: ='3-Statement Model'!L22 -> 14860 | F8: ='3-Statement Model'!M22 -> 16373.188 | G8: ='3-Statement Model'!N22 -> 18010.506 | H8: ='3-Statement Model'!O22 -> 19775.536 | I8: ='3-Statement Model'!P22 -> 21654.212 | J8: ='3-Statement Model'!Q22 -> 23668.054 | ... L8: ='3-Statement Model'!S22 -> 28197.456
B9: % Margin | C9: =C8/C5 -> 0.57323753 | D9: =D8/D5 -> 0.52280532 | E9: =E8/E5 -> 0.54209835 | F9: =F8/F5 -> 0.543 | G9: =G8/G5 -> 0.543 | H9: =H8/H5 -> 0.543 | I9: =I8/I5 -> 0.543 | J9: =J8/J5 -> 0.543 | ... L9: =L8/L5 -> 0.543
B11: EBIT | C11: ='3-Statement Model'!J24 -> 10237 | D11: ='3-Statement Model'!K24 -> 7479 | E11: ='3-Statement Model'!L24 -> 8280 | F11: ='3-Statement Model'!M24 -> 9812.9136 | G11: ='3-Statement Model'!N24 -> 10549.766 | H11: ='3-Statement Model'!O24 -> 11347.142 | I11: ='3-Statement Model'!P24 -> 12217.289 | J11: ='3-Statement Model'!Q24 -> 13181.111 | ... L11: ='3-Statement Model'!S24 -> 15536.452
B12: % Margin | C12: =C11/C5 -> 0.36412464 | D12: =D11/D5 -> 0.30214519 | E12: =E11/E5 -> 0.30205749 | F12: =F11/F5 -> 0.32543523 | G12: =G11/G5 -> 0.31806561 | H12: =H11/H5 -> 0.31157173 | I12: =I11/I5 -> 0.30636016 | J12: =J11/J5 -> 0.30240524 | ... L12: =L11/L5 -> 0.29918632
B14: NOPAT | C14: =C11*(1-'3-Statement Model'!J12) -> 8823.9344 | D14: =D11*(1-'3-Statement Model'!K12) -> 7059.0263 | E14: =E11*(1-'3-Statement Model'!L12) -> 9745.9073 | F14: =F11*(1-'3-Statement Model'!M12) -> 9224.1388 | G14: =G11*(1-'3-Statement Model'!N12) -> 9811.282 | H14: =H11*(1-'3-Statement Model'!O12) -> 10439.37 | I14: =I11*(1-'3-Statement Model'!P12) -> 11117.733 | J14: =J11*(1-'3-Statement Model'!Q12) -> 11863 | ... L14: =L11*(1-'3-Statement Model'!S12) -> 13982.807
B16: Depreciation and Amortization | C16: =-'3-Statement Model'!J23 -> 5879 | D16: =-'3-Statement Model'!K23 -> 5462 | E16: =-'3-Statement Model'!L23 -> 6580 | F16: =-'3-Statement Model'!M23 -> 6560.274 | G16: =-'3-Statement Model'!N23 -> 7460.7408 | H16: =-'3-Statement Model'!O23 -> 8428.3944 | I16: =-'3-Statement Model'!P23 -> 9436.9232 | J16: =-'3-Statement Model'!Q23 -> 10486.942 | ... L16: =-'3-Statement Model'!S23 -> 12661.005
B17: Deferred Taxes & Investment Tax Credit | C17: =0.1378*C16 -> 810.1262 | D17: =0.1378*D16 -> 752.6636 | E17: =0.1378*E16 -> 906.724 | F17: =0.1378*F16 -> 904.00576 | G17: =0.1378*G16 -> 1028.0901 | H17: =0.1378*H16 -> 1161.4328 | I17: =0.1378*I16 -> 1300.408 | J17: =0.1378*J16 -> 1445.1006 | ... L17: =0.1378*L16 -> 1744.6864
B18: Other Funds | C18: =0.052*C16 -> 305.708 | D18: =0.052*D16 -> 284.024 | E18: =0.052*E16 -> 342.16 | F18: =0.052*F16 -> 341.13425 | G18: =0.052*G16 -> 387.95852 | H18: =0.052*H16 -> 438.27651 | I18: =0.052*I16 -> 490.72001 | J18: =0.052*J16 -> 545.32099 | ... L18: =0.052*L16 -> 658.37224
B19: Funds From Operation | C19: =SUM(C16:C18)+C14 -> 15818.769 | D19: =SUM(D16:D18)+D14 -> 13557.714 | E19: =SUM(E16:E18)+E14 -> 17574.791 | F19: =SUM(F16:F18)+F14 -> 17029.553 | G19: =SUM(G16:G18)+G14 -> 18688.071 | H19: =SUM(H16:H18)+H14 -> 20467.474 | I19: =SUM(I16:I18)+I14 -> 22345.784 | J19: =SUM(J16:J18)+J14 -> 24340.364 | ... L19: =SUM(L16:L18)+L14 -> 29046.87
B21: Receivables | C21: =-0.209799*(C5-'3-Statement Model'!I18) -> -1501.7412 | D21: =-0.209799*(D5-C5) -> 705.13444 | E21: =-0.209799*(E5-D5) -> -557.85554 | F21: =-0.209799*(F5-E5) -> -575.10102 | G21: =-0.209799*(G5-F5) -> -632.61112 | H21: =-0.209799*(H5-G5) -> -681.95479 | I21: =-0.209799*(I5-H5) -> -725.86433 | J21: =-0.209799*(J5-I5) -> -778.08835 | K21: =-0.209799*(K5-J5) -> -841.30594 | L21: =-0.209799*(L5-K5) -> -908.72015
B22: Inventories | C22: =-0.088283*(C5-'3-Statement Model'!I18) -> -631.92971 | D22: =-0.088283*(D5-C5) -> 296.71916 | E22: =-0.088283*(E5-D5) -> -234.7445 | F22: =-0.088283*(F5-E5) -> -242.00136 | G22: =-0.088283*(G5-F5) -> -266.2015 | H22: =-0.088283*(H5-G5) -> -286.96521 | I22: =-0.088283*(I5-H5) -> -305.44226 | J22: =-0.088283*(J5-I5) -> -327.41802 | K22: =-0.088283*(K5-J5) -> -354.01986 | L22: =-0.088283*(L5-K5) -> -382.38762
B23: Accounts Payable | C23: =0.276631*(C5-'3-Statement Model'!I18) -> 1980.1247 | D23: =0.276631*(D5-C5) -> -929.75679 | E23: =0.276631*(E5-D5) -> 735.56183 | F23: =0.276631*(F5-E5) -> 758.3009 | G23: =0.276631*(G5-F5) -> 834.13099 | H23: =0.276631*(H5-G5) -> 899.1932 | I23: =0.276631*(I5-H5) -> 957.09024 | J23: =0.276631*(J5-I5) -> 1025.9504 | K23: =0.276631*(K5-J5) -> 1109.3061 | L23: =0.276631*(L5-K5) -> 1198.1952
B24: Other Assets/Liabilities | C24: ='3-Statement Model'!J35-SUM(C21:C23) -> -1727.4537 | D24: ='3-Statement Model'!K35-SUM(D21:D23) -> -13.096811 | E24: ='3-Statement Model'!L35-SUM(E21:E23) -> -577.96179 | F24: ='3-Statement Model'!M35-SUM(F21:F23) -> -250.09852 | G24: ='3-Statement Model'!N35-SUM(G21:G23) -> -275.10837 | H24: ='3-Statement Model'!O35-SUM(H21:H23) -> -296.56682 | I24: ='3-Statement Model'!P35-SUM(I21:I23) -> -315.6621 | J24: ='3-Statement Model'!Q35-SUM(J21:J23) -> -338.37315 | ... L24: ='3-Statement Model'!S35-SUM(L21:L23) -> -395.18199
B25: Change in Working Capital | C25: =SUM(C21:C24) -> -1881 | D25: =SUM(D21:D24) -> 59 | E25: =SUM(E21:E24) -> -635 | F25: =SUM(F21:F24) -> -308.9 | G25: =SUM(G21:G24) -> -339.79 | H25: =SUM(H21:H24) -> -366.29362 | I25: =SUM(I21:I24) -> -389.87844 | J25: =SUM(J21:J24) -> -417.92917 | ... L25: =SUM(L21:L24) -> -488.09452
B27: Capital Expenditures | C27: ='3-Statement Model'!J37 -> -25113 | D27: ='3-Statement Model'!K37 -> -24729 | E27: ='3-Statement Model'!L37 -> -24606 | F27: ='3-Statement Model'!M37 -> -27999.96 | G27: ='3-Statement Model'!N37 -> -30500.113 | H27: ='3-Statement Model'!O37 -> -32440.984 | I27: ='3-Statement Model'!P37 -> -34437.375 | J27: ='3-Statement Model'!Q37 -> -36033.413 | ... L27: ='3-Statement Model'!S37 -> -38670.501
B28: Unlevered Free Cash Flow | C28: =C19+C25+C27 -> -11175.231 | D28: =D19+D25+D27 -> -11112.286 | E28: =E19+E25+E27 -> -7666.2087 | F28: =F19+F25+F27 -> -11279.307 | G28: =G19+G25+G27 -> -12151.831 | H28: =H19+H25+H27 -> -12339.803 | I28: =I19+I25+I27 -> -12481.47 | J28: =J19+J25+J27 -> -12110.978 | ... L28: =L19+L25+L27 -> -10111.725

Sheet 16'-25' 10Ks
B2: NextEra Energy, Inc. (NEE) — 10-K Filings
B3: Fiscal yrs 2016–2025 | USD $ in millions (except per-share) | Consolidated, as reported |
B5: ($ in millions) | C5: FY2016 | D5: FY2017 | E5: FY2018 | F5: FY2019 | G5: FY2020 | H5: FY2021 | I5: FY2022 | J5: FY2023 | K5: FY2024 | L5: FY2025
B7: INCOME STATEMENT
B8: Operating revenues | C8: 16138 | D8: 17173 | E8: 16727 | F8: 19204 | G8: 17997 | H8: 17069 | I8: 20956 | J8: 28114 | K8: 24753 | L8: 27412
B10: Operating expenses:
B11: Fuel, purchased power and interchange | C11: 3992 | D11: 4071 | E11: 3732 | F11: 4363 | G11: 3539 | H11: 4527 | I11: 6389 | J11: 5457 | K11: 5029 | L11: 4944
B12: Other operations and maintenance | C12: 3529 | D12: 4713 | E12: 3333 | F12: 3874 | G12: 3934 | H12: 3981 | I12: 4428 | J12: 4681 | K12: 4857 | L12: 5399
B13: Depreciation and amortization | C13: 3120 | D13: 2357 | E13: 3911 | F13: 4216 | G13: 4052 | H13: 3924 | I13: 4503 | J13: 5879 | K13: 5462 | L13: 6580
B14: Taxes other than income taxes and other – net | C14: 1485 | D14: 1970 | E14: 1551 | F14: 1804 | G14: 1709 | H14: 1801 | I14: 2077 | J14: 2265 | K14: 2278 | L14: 2469
B15: Total operating expenses – net | C15: 12126 | D15: 13111 | E15: 12527 | F15: 14257 | G15: 13234 | H15: 14233 | I15: 17397 | J15: 18282 | K15: 17626 | L15: 19392
B16: Gains on disposal of businesses/assets – net | C16: 447 | D16: 1111 | E16: 80 | F16: 406 | G16: 353 | H16: 77 | I16: 522 | J16: 405 | K16: 352 | L16: 260
B17: OPERATING INCOME (EBIT) | C17: 4459 | D17: 5173 | E17: 4280 | F17: 5353 | G17: 5116 | H17: 2913 | I17: 4081 | J17: 10237 | K17: 7479 | L17: 8280
B18: Memo: EBITDA (operating income + D&A) | C18: 7579 | D18: 7530 | E18: 8191 | F18: 9569 | G18: 9168 | H18: 6837 | I18: 8584 | J18: 16116 | K18: 12941 | L18: 14860
B20: Other income (deductions):
B21: Interest expense | C21: -1098 | D21: -1558 | E21: -1498 | F21: -2249 | G21: -1950 | H21: -1270 | I21: -585 | J21: -3324 | K21: -2235 | L21: -4572
B22: Equity in earnings (losses) of equity method investees | C22: 148 | D22: 141 | E22: 358 | F22: 66 | G22: -1351 | H22: 666 | I22: 203 | J22: -648 | K22: -246 | L22: -184
B23: Allowance for equity funds used during construction | C23: 86 | D23: 92 | E23: 96 | F23: 67 | G23: 93 | H23: 142 | I23: 112 | J23: 161 | K23: 198 | L23: 181
B24: Gains on disposal of investments & other property – net | C24: 40 | D24: 112 | E24: 111 | F24: 55 | G24: 50 | H24: 70 | I24: 80 | J24: 125 | K24: 163 | L24: 179
B25: Change in unrealized gains (losses) on equity secs – NDF | E25: -189 | F25: 238 | G25: 163 | H25: 267 | I25: -461 | J25: 159 | K25: 107 | L25: 107
B26: Other net periodic benefit income | C26: 144 | D26: 151 | E26: 168 | F26: 185 | G26: 200 | H26: 257 | I26: 202 | J26: 245 | K26: 235 | L26: 267
B27: Other – net | C27: 19 | D27: 11 | E27: 48 | F27: 67 | G27: 54 | H27: 130 | I27: 200 | J27: 333 | K27: 336 | L27: 272
B28: Total other income (deductions) – net | C28: -81 | D28: -510 | E28: 3072 | F28: -1517 | G28: -2703 | H28: 262 | I28: -249 | J28: -2949 | K28: -1442 | L28: -3750
B29: INCOME BEFORE INCOME TAXES (EBT) | C29: 4378 | D29: 4663 | E29: 7352 | F29: 3836 | G29: 2413 | H29: 3175 | I29: 3832 | J29: 7288 | K29: 6037 | L29: 4530
B30: Income tax expense (benefit) | C30: 1379 | D30: -660 | E30: 1576 | F30: 448 | G30: 44 | H30: 348 | I30: 586 | J30: 1006 | K30: 339 | L30: -802
B31: NET INCOME (incl. noncontrolling interests) | C31: 2999 | D31: 5323 | E31: 5776 | F31: 3388 | G31: 2369 | H31: 2827 | I31: 3246 | J31: 6282 | K31: 5698 | L31: 5332
B32: Net loss attributable to noncontrolling interests | C32: -93 | D32: 57 | E32: 862 | F32: 381 | G32: 550 | H32: 746 | I32: 901 | J32: 1028 | K32: 1248 | L32: 1503
B33: NET INCOME ATTRIBUTABLE TO NEE | C33: 2906 | D33: 5380 | E33: 6638 | F33: 3769 | G33: 2919 | H33: 3573 | I33: 4147 | J33: 7310 | K33: 6946 | L33: 6835
B34: Earnings per share – basic ($) | C34: 1.57 | D34: 2.87 | E34: 3.51 | F34: 1.95 | G34: 1.49 | H34: 1.82 | I34: 2.1 | J34: 3.61 | K34: 3.38 | L34: 3.31
B35: Earnings per share – diluted ($) | C35: 1.56 | D35: 2.85 | E35: 3.47 | F35: 1.94 | G35: 1.48 | H35: 1.81 | I35: 2.1 | J35: 3.6 | K35: 3.37 | L35: 3.3
B38: CASH FLOW STATEMENT
B39: Operating activities:
B40: Net income | C40: 2999 | D40: 5323 | E40: 5776 | F40: 3388 | G40: 2369 | H40: 2827 | I40: 3246 | J40: 6282 | K40: 5698 | L40: 5332
B41: Depreciation and amortization | C41: 3120 | D41: 2357 | E41: 3911 | F41: 4216 | G41: 4052 | H41: 3924 | I41: 4503 | J41: 5879 | K41: 5462 | L41: 6580
B42: Nuclear fuel and other amortization | C42: 308 | D42: 281 | E42: 236 | F42: 262 | G42: 263 | H42: 290 | I42: 287 | J42: 272 | K42: 299 | L42: 361
B43: Unrealized losses (gains) on MtM derivatives – net | C43: -44 | D43: 436 | E43: 54 | F43: -108 | G43: 533 | H43: 2005 | I43: 1378 | J43: -1949 | K43: -492 | L43: 199
B44: Unrealized losses (gains) on equity securities – NDF | G44: -163 | H44: -267 | I44: 461 | J44: -159 | K44: -107 | L44: -107
B45: Foreign currency transaction losses (gains) | C45: 13 | D45: -25 | E45: 16 | F45: 17 | G45: 45 | H45: -94 | I45: -104 | J45: 92 | K45: -85 | L45: 110
B46: Deferred income taxes | C46: 1226 | D46: -882 | E46: 1463 | F46: 258 | G46: -78 | H46: 436 | I46: 534 | J46: 708 | K46: 1308 | L46: 453
B47: Cost recovery clauses and franchise fees | C47: 94 | D47: 82 | E47: -225 | F47: 155 | G47: -121 | H47: -599 | I47: -1465 | J47: 1104 | K47: 1016 | L47: -89
...

Sheet DDM Assumptions
B2: DDM Assumptions — NextEra Energy, Inc. (NEE)
B3: Valuation Date: 08/03/2026
B5: Cost of Equity (CAPM)
B6: Risk-free rate | C6: ='DDM Model'!D6 -> 0.04652
B7: Equity risk premium | C7: ='DDM Model'!D7 -> 0.0446
B8: Levered beta | C8: ='DDM Model'!D8 -> 0.42672131
B9: Cost of equity (rf + β × ERP) | C9: ='DDM Model'!D9 -> 0.06555177
B11: Dividend & Valuation Inputs
B12: Base-year dividend / share (2025A) | C12: ='DDM Model'!D12 -> 2.27
B13: Current share price ($) | C13: ='DDM Model'!D13 -> 86.55
B14: Terminal growth rate (g∞) | C14: ='DDM Model'!D15 -> 0.03
B18: FPL segment comparables
B19: Ticker | C19: Levered β | D19: Marg. tax | E19: D/E | F19: Unlevered β
B20: DTE | C20: 0.4 | D20: 0.21 | E20: 0.87 | F20: =IFERROR(C20/(1+(1-D20)*E20),"") -> 0.23706513
B21: CMS | C21: 0.34 | D21: 0.21 | E21: 0.83 | F21: =IFERROR(C21/(1+(1-D21)*E21),"") -> 0.20535121
B22: EVRG | C22: 0.51 | D22: 0.21 | E22: 0.87 | F22: =IFERROR(C22/(1+(1-D22)*E22),"") -> 0.30225805
B23: DUK | C23: 0.37 | D23: 0.21 | E23: 0.9 | F23: =IFERROR(C23/(1+(1-D23)*E23),"") -> 0.21624781
B24: PNW | C24: 0.44 | D24: 0.21 | E24: 0.87 | F24: =IFERROR(C24/(1+(1-D24)*E24),"") -> 0.26077165
B25: ETR | C25: 0.49 | D25: 0.21 | E25: 0.73 | F25: =IFERROR(C25/(1+(1-D25)*E25),"") -> 0.31077567
B26: AEE | C26: 0.48 | D26: 0.21 | E26: 0.79 | F26: =IFERROR(C26/(1+(1-D26)*E26),"") -> 0.2955483
B27: XEL | C27: 0.41 | D27: 0.21 | E27: 0.83 | F27: =IFERROR(C27/(1+(1-D27)*E27),"") -> 0.2476294
B28: SO | C28: 0.33 | D28: 0.21 | E28: 0.76 | F28: =IFERROR(C28/(1+(1-D28)*E28),"") -> 0.20619845
B29: LNT | C29: 0.54 | D29: 0.21 | E29: 0.69 | F29: =IFERROR(C29/(1+(1-D29)*E29),"") -> 0.34949194
B30: Average unlevered β — FPL | F30: =IFERROR(AVERAGE(F20:F29),"") -> 0.26313376
B32: NEER segment comparables
B33: Ticker | C33: Levered β | D33: Marg. tax | E33: D/E | F33: Unlevered β
B34: ENGI | C34: 0.56 | D34: 0.258 | E34: 0.97 | F34: =IFERROR(C34/(1+(1-D34)*E34),"") -> 0.32563062
B35: RWE | C35: 0.57 | D35: 0.3 | E35: 0.59 | F35: =IFERROR(C35/(1+(1-D35)*E35),"") -> 0.40339703
B36: AES | C36: 0.95 | D36: 0.21 | E36: 2.96 | F36: =IFERROR(C36/(1+(1-D36)*E36),"") -> 0.28456746
B37: IBE | C37: 0.56 | D37: 0.25 | E37: 0.43 | F37: =IFERROR(C37/(1+(1-D37)*E37),"") -> 0.42344045
B38: EDPR | C38: 0.75 | D38: 0.25 | E38: 0.97 | F38: =IFERROR(C38/(1+(1-D38)*E38),"") -> 0.4341534
B39: SSE | C39: 0.58 | D39: 0.25 | E39: 0.51 | F39: =IFERROR(C39/(1+(1-D39)*E39),"") -> 0.41952984
B40: BEP | C40: 1 | D40: 0.265 | E40: 1.92 | F40: =IFERROR(C40/(1+(1-D40)*E40),"") -> 0.41473125
B41: CWEN | C41: 0.88 | D41: 0.21 | E41: 1.12 | F41: =IFERROR(C41/(1+(1-D41)*E41),"") -> 0.46689304
B42: NPI | C42: 0.62 | D42: 0.265 | E42: 1.12 | F42: =IFERROR(C42/(1+(1-D42)*E42),"") -> 0.34006143
B43: CPX | C43: 0.41 | D43: 0.23 | E43: 0.74 | F43: =IFERROR(C43/(1+(1-D43)*E43),"") -> 0.26117977
B44: Average unlevered β — NEER | F44: =IFERROR(AVERAGE(F34:F43),"") -> 0.37735843
B46: NEE bottom-up beta
B47: FPL unlevered β | D47: =F30 -> 0.26313376
B48: FPL weight (% of revenue) | D48: 0.655
...
